[2025-02-27T00:20:31.238+0000] {logging_mixin.py:151} WARNING - /home/***/.local/lib/python3.8/site-packages/***/utils/sqlalchemy.py:124 DeprecationWarning: The sql_alchemy_conn option in [core] has been moved to the sql_alchemy_conn option in [database] - the old setting has been used, but please update your config.
[2025-02-27T00:20:31.247+0000] {taskinstance.py:1149} INFO - Dependencies not met for <TaskInstance: coingecko_ingestion_dag.fetch_data scheduled__2025-02-26T00:00:00+00:00 [up_for_retry]>, dependency 'Not In Retry Period' FAILED: Task is not ready for retry yet but will be retried automatically. Current date is 2025-02-27T00:20:31.247058+00:00 and task will be retried at 2025-02-27T00:25:29.182415+00:00.
[2025-02-27T00:20:31.263+0000] {local_task_job_runner.py:154} INFO - Task is not able to be run
[2025-02-27T00:25:30.873+0000] {logging_mixin.py:151} WARNING - /home/***/.local/lib/python3.8/site-packages/***/utils/sqlalchemy.py:124 DeprecationWarning: The sql_alchemy_conn option in [core] has been moved to the sql_alchemy_conn option in [database] - the old setting has been used, but please update your config.
[2025-02-27T00:25:30.888+0000] {taskinstance.py:1159} INFO - Dependencies all met for dep_context=non-requeueable deps ti=<TaskInstance: coingecko_ingestion_dag.fetch_data scheduled__2025-02-26T00:00:00+00:00 [queued]>
[2025-02-27T00:25:30.901+0000] {taskinstance.py:1159} INFO - Dependencies all met for dep_context=requeueable deps ti=<TaskInstance: coingecko_ingestion_dag.fetch_data scheduled__2025-02-26T00:00:00+00:00 [queued]>
[2025-02-27T00:25:30.902+0000] {taskinstance.py:1361} INFO - Starting attempt 2 of 2
[2025-02-27T00:25:30.921+0000] {taskinstance.py:1382} INFO - Executing <Task(PythonOperator): fetch_data> on 2025-02-26 00:00:00+00:00
[2025-02-27T00:25:30.926+0000] {standard_task_runner.py:57} INFO - Started process 303 to run task
[2025-02-27T00:25:30.932+0000] {standard_task_runner.py:84} INFO - Running: ['***', 'tasks', 'run', 'coingecko_ingestion_dag', 'fetch_data', 'scheduled__2025-02-26T00:00:00+00:00', '--job-id', '9', '--raw', '--subdir', 'DAGS_FOLDER/coingecko_pipeline.py', '--cfg-path', '/tmp/tmp3toa9zc7']
[2025-02-27T00:25:30.936+0000] {standard_task_runner.py:85} INFO - Job 9: Subtask fetch_data
[2025-02-27T00:25:30.960+0000] {logging_mixin.py:151} WARNING - /home/***/.local/lib/python3.8/site-packages/***/settings.py:195 DeprecationWarning: The sql_alchemy_conn option in [core] has been moved to the sql_alchemy_conn option in [database] - the old setting has been used, but please update your config.
[2025-02-27T00:25:31.018+0000] {task_command.py:415} INFO - Running <TaskInstance: coingecko_ingestion_dag.fetch_data scheduled__2025-02-26T00:00:00+00:00 [running]> on host df63850bb5b8
[2025-02-27T00:25:31.034+0000] {logging_mixin.py:151} WARNING - /home/***/.local/lib/python3.8/site-packages/***/utils/sqlalchemy.py:124 DeprecationWarning: The sql_alchemy_conn option in [core] has been moved to the sql_alchemy_conn option in [database] - the old setting has been used, but please update your config.
[2025-02-27T00:25:31.194+0000] {taskinstance.py:1660} INFO - Exporting env vars: AIRFLOW_CTX_DAG_OWNER='etudiant' AIRFLOW_CTX_DAG_ID='coingecko_ingestion_dag' AIRFLOW_CTX_TASK_ID='fetch_data' AIRFLOW_CTX_EXECUTION_DATE='2025-02-26T00:00:00+00:00' AIRFLOW_CTX_TRY_NUMBER='2' AIRFLOW_CTX_DAG_RUN_ID='scheduled__2025-02-26T00:00:00+00:00'
[2025-02-27T00:25:31.216+0000] {taskinstance.py:1943} ERROR - Task failed with exception
Traceback (most recent call last):
  File "/home/airflow/.local/lib/python3.8/site-packages/urllib3/connection.py", line 174, in _new_conn
    conn = connection.create_connection(
  File "/home/airflow/.local/lib/python3.8/site-packages/urllib3/util/connection.py", line 72, in create_connection
    for res in socket.getaddrinfo(host, port, family, socket.SOCK_STREAM):
  File "/usr/local/lib/python3.8/socket.py", line 918, in getaddrinfo
    for res in _socket.getaddrinfo(host, port, family, type, proto, flags):
socket.gaierror: [Errno -2] Name or service not known

During handling of the above exception, another exception occurred:

Traceback (most recent call last):
  File "/home/airflow/.local/lib/python3.8/site-packages/urllib3/connectionpool.py", line 714, in urlopen
    httplib_response = self._make_request(
  File "/home/airflow/.local/lib/python3.8/site-packages/urllib3/connectionpool.py", line 403, in _make_request
    self._validate_conn(conn)
  File "/home/airflow/.local/lib/python3.8/site-packages/urllib3/connectionpool.py", line 1053, in _validate_conn
    conn.connect()
  File "/home/airflow/.local/lib/python3.8/site-packages/urllib3/connection.py", line 363, in connect
    self.sock = conn = self._new_conn()
  File "/home/airflow/.local/lib/python3.8/site-packages/urllib3/connection.py", line 186, in _new_conn
    raise NewConnectionError(
urllib3.exceptions.NewConnectionError: <urllib3.connection.HTTPSConnection object at 0x7f38bdacb400>: Failed to establish a new connection: [Errno -2] Name or service not known

During handling of the above exception, another exception occurred:

Traceback (most recent call last):
  File "/home/airflow/.local/lib/python3.8/site-packages/requests/adapters.py", line 486, in send
    resp = conn.urlopen(
  File "/home/airflow/.local/lib/python3.8/site-packages/urllib3/connectionpool.py", line 798, in urlopen
    retries = retries.increment(
  File "/home/airflow/.local/lib/python3.8/site-packages/urllib3/util/retry.py", line 592, in increment
    raise MaxRetryError(_pool, url, error or ResponseError(cause))
urllib3.exceptions.MaxRetryError: HTTPSConnectionPool(host='api.coingecko.com', port=443): Max retries exceeded with url: /api/v3/coins/markets?vs_currency=usd&order=market_cap_desc&per_page=100&page=1&sparkline=false (Caused by NewConnectionError('<urllib3.connection.HTTPSConnection object at 0x7f38bdacb400>: Failed to establish a new connection: [Errno -2] Name or service not known'))

During handling of the above exception, another exception occurred:

Traceback (most recent call last):
  File "/home/airflow/.local/lib/python3.8/site-packages/airflow/operators/python.py", line 192, in execute
    return_value = self.execute_callable()
  File "/home/airflow/.local/lib/python3.8/site-packages/airflow/operators/python.py", line 209, in execute_callable
    return self.python_callable(*self.op_args, **self.op_kwargs)
  File "/opt/airflow/dags/coingecko_pipeline.py", line 27, in fetch_coingecko_data
    response = requests.get(url, params=params)
  File "/home/airflow/.local/lib/python3.8/site-packages/requests/api.py", line 73, in get
    return request("get", url, params=params, **kwargs)
  File "/home/airflow/.local/lib/python3.8/site-packages/requests/api.py", line 59, in request
    return session.request(method=method, url=url, **kwargs)
  File "/home/airflow/.local/lib/python3.8/site-packages/requests/sessions.py", line 589, in request
    resp = self.send(prep, **send_kwargs)
  File "/home/airflow/.local/lib/python3.8/site-packages/requests/sessions.py", line 703, in send
    r = adapter.send(request, **kwargs)
  File "/home/airflow/.local/lib/python3.8/site-packages/requests/adapters.py", line 519, in send
    raise ConnectionError(e, request=request)
requests.exceptions.ConnectionError: HTTPSConnectionPool(host='api.coingecko.com', port=443): Max retries exceeded with url: /api/v3/coins/markets?vs_currency=usd&order=market_cap_desc&per_page=100&page=1&sparkline=false (Caused by NewConnectionError('<urllib3.connection.HTTPSConnection object at 0x7f38bdacb400>: Failed to establish a new connection: [Errno -2] Name or service not known'))
[2025-02-27T00:25:31.240+0000] {taskinstance.py:1400} INFO - Marking task as FAILED. dag_id=coingecko_ingestion_dag, task_id=fetch_data, execution_date=20250226T000000, start_date=20250227T002530, end_date=20250227T002531
[2025-02-27T00:25:31.269+0000] {standard_task_runner.py:104} ERROR - Failed to execute job 9 for task fetch_data (HTTPSConnectionPool(host='api.coingecko.com', port=443): Max retries exceeded with url: /api/v3/coins/markets?vs_currency=usd&order=market_cap_desc&per_page=100&page=1&sparkline=false (Caused by NewConnectionError('<urllib3.connection.HTTPSConnection object at 0x7f38bdacb400>: Failed to establish a new connection: [Errno -2] Name or service not known')); 303)
[2025-02-27T00:25:31.316+0000] {local_task_job_runner.py:228} INFO - Task exited with return code 1
[2025-02-27T00:25:31.368+0000] {taskinstance.py:2784} INFO - 0 downstream tasks scheduled from follow-on schedule check
